[2024-11-11T07:22:38.156+0000] {local_task_job_runner.py:123} INFO - ::group::Pre task execution logs
[2024-11-11T07:22:38.183+0000] {taskinstance.py:2612} INFO - Dependencies all met for dep_context=non-requeueable deps ti=<TaskInstance: python_op_sample_1.create_save_df manual__2024-11-11T07:22:35.122189+00:00 [queued]>
[2024-11-11T07:22:38.196+0000] {taskinstance.py:2612} INFO - Dependencies all met for dep_context=requeueable deps ti=<TaskInstance: python_op_sample_1.create_save_df manual__2024-11-11T07:22:35.122189+00:00 [queued]>
[2024-11-11T07:22:38.196+0000] {taskinstance.py:2865} INFO - Starting attempt 1 of 2
[2024-11-11T07:22:38.218+0000] {taskinstance.py:2888} INFO - Executing <Task(PythonOperator): create_save_df> on 2024-11-11 07:22:35.122189+00:00
[2024-11-11T07:22:38.231+0000] {warnings.py:112} WARNING - /home/***/.local/lib/python3.12/site-packages/***/task/task_runner/standard_task_runner.py:70: DeprecationWarning: This process (pid=55133) is multi-threaded, use of fork() may lead to deadlocks in the child.
  pid = os.fork()

[2024-11-11T07:22:38.235+0000] {standard_task_runner.py:72} INFO - Started process 55135 to run task
[2024-11-11T07:22:38.235+0000] {standard_task_runner.py:104} INFO - Running: ['***', 'tasks', 'run', 'python_op_sample_1', 'create_save_df', 'manual__2024-11-11T07:22:35.122189+00:00', '--job-id', '26', '--raw', '--subdir', 'DAGS_FOLDER/dag1_py_op_sample.py', '--cfg-path', '/tmp/tmp4lh398ma']
[2024-11-11T07:22:38.237+0000] {standard_task_runner.py:105} INFO - Job 26: Subtask create_save_df
[2024-11-11T07:22:38.326+0000] {task_command.py:467} INFO - Running <TaskInstance: python_op_sample_1.create_save_df manual__2024-11-11T07:22:35.122189+00:00 [running]> on host b86342c5c47f
[2024-11-11T07:22:38.476+0000] {taskinstance.py:3131} INFO - Exporting env vars: AIRFLOW_CTX_DAG_OWNER='***' AIRFLOW_CTX_DAG_ID='python_op_sample_1' AIRFLOW_CTX_TASK_ID='create_save_df' AIRFLOW_CTX_EXECUTION_DATE='2024-11-11T07:22:35.122189+00:00' AIRFLOW_CTX_TRY_NUMBER='1' AIRFLOW_CTX_DAG_RUN_ID='manual__2024-11-11T07:22:35.122189+00:00'
[2024-11-11T07:22:38.478+0000] {logging_mixin.py:190} INFO - Task instance is in running state
[2024-11-11T07:22:38.479+0000] {logging_mixin.py:190} INFO -  Previous state of the Task instance: queued
[2024-11-11T07:22:38.480+0000] {logging_mixin.py:190} INFO - Current task name:create_save_df state:running start_date:2024-11-11 07:22:38.184247+00:00
[2024-11-11T07:22:38.481+0000] {logging_mixin.py:190} INFO - Dag name:python_op_sample_1 and current dag run status:running
[2024-11-11T07:22:38.482+0000] {taskinstance.py:731} INFO - ::endgroup::
[2024-11-11T07:22:38.483+0000] {taskinstance.py:3310} ERROR - Task failed with exception
Traceback (most recent call last):
  File "/home/airflow/.local/lib/python3.12/site-packages/airflow/models/taskinstance.py", line 767, in _execute_task
    result = _execute_callable(context=context, **execute_callable_kwargs)
             ^^^^^^^^^^^^^^^^^^^^^^^^^^^^^^^^^^^^^^^^^^^^^^^^^^^^^^^^^^^^^
  File "/home/airflow/.local/lib/python3.12/site-packages/airflow/models/taskinstance.py", line 733, in _execute_callable
    return ExecutionCallableRunner(
           ^^^^^^^^^^^^^^^^^^^^^^^^
  File "/home/airflow/.local/lib/python3.12/site-packages/airflow/utils/operator_helpers.py", line 252, in run
    return self.func(*args, **kwargs)
           ^^^^^^^^^^^^^^^^^^^^^^^^^^
  File "/home/airflow/.local/lib/python3.12/site-packages/airflow/models/baseoperator.py", line 406, in wrapper
    return func(self, *args, **kwargs)
           ^^^^^^^^^^^^^^^^^^^^^^^^^^^
  File "/home/airflow/.local/lib/python3.12/site-packages/airflow/operators/python.py", line 238, in execute
    return_value = self.execute_callable()
                   ^^^^^^^^^^^^^^^^^^^^^^^
  File "/home/airflow/.local/lib/python3.12/site-packages/airflow/operators/python.py", line 256, in execute_callable
    return runner.run(*self.op_args, **self.op_kwargs)
           ^^^^^^^^^^^^^^^^^^^^^^^^^^^^^^^^^^^^^^^^^^^
  File "/home/airflow/.local/lib/python3.12/site-packages/airflow/utils/operator_helpers.py", line 252, in run
    return self.func(*args, **kwargs)
           ^^^^^^^^^^^^^^^^^^^^^^^^^^
  File "/opt/airflow/dags/dag_1_python_op_eg/task1.py", line 5, in create_and_save_df
    current_path = os.getcwd()
                   ^^
NameError: name 'os' is not defined. Did you forget to import 'os'
[2024-11-11T07:22:38.514+0000] {logging_mixin.py:190} INFO - Task instance in failure state
[2024-11-11T07:22:38.515+0000] {logging_mixin.py:190} INFO - Task start:2024-11-11 07:22:38.184247+00:00 end:2024-11-11 07:22:38.513916+00:00 duration:0.329669
[2024-11-11T07:22:38.515+0000] {logging_mixin.py:190} INFO - Task:<Task(PythonOperator): create_save_df> dag:<DAG: python_op_sample_1> dagrun:<DagRun python_op_sample_1 @ 2024-11-11 07:22:35.122189+00:00: manual__2024-11-11T07:22:35.122189+00:00, state:running, queued_at: 2024-11-11 07:22:35.193737+00:00. externally triggered: True>
[2024-11-11T07:22:38.516+0000] {logging_mixin.py:190} INFO - Failure caused by name 'os' is not defined
[2024-11-11T07:22:38.517+0000] {taskinstance.py:1225} INFO - Marking task as UP_FOR_RETRY. dag_id=python_op_sample_1, task_id=create_save_df, run_id=manual__2024-11-11T07:22:35.122189+00:00, execution_date=20241111T072235, start_date=20241111T072238, end_date=20241111T072238
[2024-11-11T07:22:38.553+0000] {taskinstance.py:340} INFO - ::group::Post task execution logs
[2024-11-11T07:22:38.554+0000] {standard_task_runner.py:124} ERROR - Failed to execute job 26 for task create_save_df (name 'os' is not defined; 55135)
Traceback (most recent call last):
  File "/home/airflow/.local/lib/python3.12/site-packages/airflow/task/task_runner/standard_task_runner.py", line 117, in _start_by_fork
    ret = args.func(args, dag=self.dag)
          ^^^^^^^^^^^^^^^^^^^^^^^^^^^^^
  File "/home/airflow/.local/lib/python3.12/site-packages/airflow/cli/cli_config.py", line 49, in command
    return func(*args, **kwargs)
           ^^^^^^^^^^^^^^^^^^^^^
  File "/home/airflow/.local/lib/python3.12/site-packages/airflow/utils/cli.py", line 115, in wrapper
    return f(*args, **kwargs)
           ^^^^^^^^^^^^^^^^^^
  File "/home/airflow/.local/lib/python3.12/site-packages/airflow/cli/commands/task_command.py", line 483, in task_run
    task_return_code = _run_task_by_selected_method(args, _dag, ti)
                       ^^^^^^^^^^^^^^^^^^^^^^^^^^^^^^^^^^^^^^^^^^^^
  File "/home/airflow/.local/lib/python3.12/site-packages/airflow/cli/commands/task_command.py", line 256, in _run_task_by_selected_method
    return _run_raw_task(args, ti)
           ^^^^^^^^^^^^^^^^^^^^^^^
  File "/home/airflow/.local/lib/python3.12/site-packages/airflow/cli/commands/task_command.py", line 341, in _run_raw_task
    return ti._run_raw_task(
           ^^^^^^^^^^^^^^^^^
  File "/home/airflow/.local/lib/python3.12/site-packages/airflow/utils/session.py", line 97, in wrapper
    return func(*args, session=session, **kwargs)
           ^^^^^^^^^^^^^^^^^^^^^^^^^^^^^^^^^^^^^^
  File "/home/airflow/.local/lib/python3.12/site-packages/airflow/models/taskinstance.py", line 3004, in _run_raw_task
    return _run_raw_task(
           ^^^^^^^^^^^^^^
  File "/home/airflow/.local/lib/python3.12/site-packages/airflow/models/taskinstance.py", line 273, in _run_raw_task
    TaskInstance._execute_task_with_callbacks(
  File "/home/airflow/.local/lib/python3.12/site-packages/airflow/models/taskinstance.py", line 3158, in _execute_task_with_callbacks
    result = self._execute_task(context, task_orig)
             ^^^^^^^^^^^^^^^^^^^^^^^^^^^^^^^^^^^^^^
  File "/home/airflow/.local/lib/python3.12/site-packages/airflow/models/taskinstance.py", line 3182, in _execute_task
    return _execute_task(self, context, task_orig)
           ^^^^^^^^^^^^^^^^^^^^^^^^^^^^^^^^^^^^^^^
  File "/home/airflow/.local/lib/python3.12/site-packages/airflow/models/taskinstance.py", line 767, in _execute_task
    result = _execute_callable(context=context, **execute_callable_kwargs)
             ^^^^^^^^^^^^^^^^^^^^^^^^^^^^^^^^^^^^^^^^^^^^^^^^^^^^^^^^^^^^^
  File "/home/airflow/.local/lib/python3.12/site-packages/airflow/models/taskinstance.py", line 733, in _execute_callable
    return ExecutionCallableRunner(
           ^^^^^^^^^^^^^^^^^^^^^^^^
  File "/home/airflow/.local/lib/python3.12/site-packages/airflow/utils/operator_helpers.py", line 252, in run
    return self.func(*args, **kwargs)
           ^^^^^^^^^^^^^^^^^^^^^^^^^^
  File "/home/airflow/.local/lib/python3.12/site-packages/airflow/models/baseoperator.py", line 406, in wrapper
    return func(self, *args, **kwargs)
           ^^^^^^^^^^^^^^^^^^^^^^^^^^^
  File "/home/airflow/.local/lib/python3.12/site-packages/airflow/operators/python.py", line 238, in execute
    return_value = self.execute_callable()
                   ^^^^^^^^^^^^^^^^^^^^^^^
  File "/home/airflow/.local/lib/python3.12/site-packages/airflow/operators/python.py", line 256, in execute_callable
    return runner.run(*self.op_args, **self.op_kwargs)
           ^^^^^^^^^^^^^^^^^^^^^^^^^^^^^^^^^^^^^^^^^^^
  File "/home/airflow/.local/lib/python3.12/site-packages/airflow/utils/operator_helpers.py", line 252, in run
    return self.func(*args, **kwargs)
           ^^^^^^^^^^^^^^^^^^^^^^^^^^
  File "/opt/airflow/dags/dag_1_python_op_eg/task1.py", line 5, in create_and_save_df
    current_path = os.getcwd()
                   ^^
NameError: name 'os' is not defined. Did you forget to import 'os'
[2024-11-11T07:22:38.615+0000] {local_task_job_runner.py:266} INFO - Task exited with return code 1
[2024-11-11T07:22:38.653+0000] {taskinstance.py:3900} INFO - 0 downstream tasks scheduled from follow-on schedule check
[2024-11-11T07:22:38.656+0000] {local_task_job_runner.py:245} INFO - ::endgroup::
