[2024-11-11T11:05:18.364+0000] {local_task_job_runner.py:123} INFO - ::group::Pre task execution logs
[2024-11-11T11:05:18.404+0000] {taskinstance.py:2612} INFO - Dependencies all met for dep_context=non-requeueable deps ti=<TaskInstance: python_op_sample_1.create_save_df manual__2024-11-11T11:05:15.719479+00:00 [queued]>
[2024-11-11T11:05:18.422+0000] {taskinstance.py:2612} INFO - Dependencies all met for dep_context=requeueable deps ti=<TaskInstance: python_op_sample_1.create_save_df manual__2024-11-11T11:05:15.719479+00:00 [queued]>
[2024-11-11T11:05:18.423+0000] {taskinstance.py:2865} INFO - Starting attempt 1 of 2
[2024-11-11T11:05:18.462+0000] {taskinstance.py:2888} INFO - Executing <Task(PythonOperator): create_save_df> on 2024-11-11 11:05:15.719479+00:00
[2024-11-11T11:05:18.480+0000] {warnings.py:112} WARNING - /home/***/.local/lib/python3.12/site-packages/***/task/task_runner/standard_task_runner.py:70: DeprecationWarning: This process (pid=57889) is multi-threaded, use of fork() may lead to deadlocks in the child.
  pid = os.fork()

[2024-11-11T11:05:18.483+0000] {standard_task_runner.py:72} INFO - Started process 57891 to run task
[2024-11-11T11:05:18.484+0000] {standard_task_runner.py:104} INFO - Running: ['***', 'tasks', 'run', 'python_op_sample_1', 'create_save_df', 'manual__2024-11-11T11:05:15.719479+00:00', '--job-id', '31', '--raw', '--subdir', 'DAGS_FOLDER/dag1_py_op_sample.py', '--cfg-path', '/tmp/tmphj9m031_']
[2024-11-11T11:05:18.487+0000] {standard_task_runner.py:105} INFO - Job 31: Subtask create_save_df
[2024-11-11T11:05:18.603+0000] {task_command.py:467} INFO - Running <TaskInstance: python_op_sample_1.create_save_df manual__2024-11-11T11:05:15.719479+00:00 [running]> on host b86342c5c47f
[2024-11-11T11:05:18.844+0000] {taskinstance.py:3131} INFO - Exporting env vars: AIRFLOW_CTX_DAG_OWNER='***' AIRFLOW_CTX_DAG_ID='python_op_sample_1' AIRFLOW_CTX_TASK_ID='create_save_df' AIRFLOW_CTX_EXECUTION_DATE='2024-11-11T11:05:15.719479+00:00' AIRFLOW_CTX_TRY_NUMBER='1' AIRFLOW_CTX_DAG_RUN_ID='manual__2024-11-11T11:05:15.719479+00:00'
[2024-11-11T11:05:18.850+0000] {logging_mixin.py:190} INFO - Task instance is in running state
[2024-11-11T11:05:18.851+0000] {logging_mixin.py:190} INFO -  Previous state of the Task instance: queued
[2024-11-11T11:05:18.852+0000] {logging_mixin.py:190} INFO - Current task name:create_save_df state:running start_date:2024-11-11 11:05:18.405445+00:00
[2024-11-11T11:05:18.852+0000] {logging_mixin.py:190} INFO - Dag name:python_op_sample_1 and current dag run status:running
[2024-11-11T11:05:18.853+0000] {taskinstance.py:731} INFO - ::endgroup::
[2024-11-11T11:05:18.856+0000] {logging_mixin.py:190} INFO - Current Path: /opt/***
[2024-11-11T11:05:18.857+0000] {logging_mixin.py:190} INFO - Starting with the first task in my Python Op Dag
[2024-11-11T11:05:18.864+0000] {logging_mixin.py:190} INFO - /opt/***/__file__
[2024-11-11T11:05:18.879+0000] {taskinstance.py:3310} ERROR - Task failed with exception
Traceback (most recent call last):
  File "/home/airflow/.local/lib/python3.12/site-packages/airflow/models/taskinstance.py", line 767, in _execute_task
    result = _execute_callable(context=context, **execute_callable_kwargs)
             ^^^^^^^^^^^^^^^^^^^^^^^^^^^^^^^^^^^^^^^^^^^^^^^^^^^^^^^^^^^^^
  File "/home/airflow/.local/lib/python3.12/site-packages/airflow/models/taskinstance.py", line 733, in _execute_callable
    return ExecutionCallableRunner(
           ^^^^^^^^^^^^^^^^^^^^^^^^
  File "/home/airflow/.local/lib/python3.12/site-packages/airflow/utils/operator_helpers.py", line 252, in run
    return self.func(*args, **kwargs)
           ^^^^^^^^^^^^^^^^^^^^^^^^^^
  File "/home/airflow/.local/lib/python3.12/site-packages/airflow/models/baseoperator.py", line 406, in wrapper
    return func(self, *args, **kwargs)
           ^^^^^^^^^^^^^^^^^^^^^^^^^^^
  File "/home/airflow/.local/lib/python3.12/site-packages/airflow/operators/python.py", line 238, in execute
    return_value = self.execute_callable()
                   ^^^^^^^^^^^^^^^^^^^^^^^
  File "/home/airflow/.local/lib/python3.12/site-packages/airflow/operators/python.py", line 256, in execute_callable
    return runner.run(*self.op_args, **self.op_kwargs)
           ^^^^^^^^^^^^^^^^^^^^^^^^^^^^^^^^^^^^^^^^^^^
  File "/home/airflow/.local/lib/python3.12/site-packages/airflow/utils/operator_helpers.py", line 252, in run
    return self.func(*args, **kwargs)
           ^^^^^^^^^^^^^^^^^^^^^^^^^^
  File "/opt/airflow/dags/dag_1_python_op_eg/task1.py", line 11, in create_and_save_df
    data.to_csv(f"{file_path}/py_op_task1.csv", index=False)
  File "/home/airflow/.local/lib/python3.12/site-packages/pandas/core/generic.py", line 3902, in to_csv
    return DataFrameRenderer(formatter).to_csv(
           ^^^^^^^^^^^^^^^^^^^^^^^^^^^^^^^^^^^^
  File "/home/airflow/.local/lib/python3.12/site-packages/pandas/io/formats/format.py", line 1152, in to_csv
    csv_formatter.save()
  File "/home/airflow/.local/lib/python3.12/site-packages/pandas/io/formats/csvs.py", line 247, in save
    with get_handle(
         ^^^^^^^^^^^
  File "/home/airflow/.local/lib/python3.12/site-packages/pandas/io/common.py", line 739, in get_handle
    check_parent_directory(str(handle))
  File "/home/airflow/.local/lib/python3.12/site-packages/pandas/io/common.py", line 604, in check_parent_directory
    raise OSError(rf"Cannot save file into a non-existent directory: '{parent}'")
OSError: Cannot save file into a non-existent directory: '/opt/***/__file__'
[2024-11-11T11:05:18.944+0000] {logging_mixin.py:190} INFO - Task instance in failure state
[2024-11-11T11:05:18.946+0000] {logging_mixin.py:190} INFO - Task start:2024-11-11 11:05:18.405445+00:00 end:2024-11-11 11:05:18.942056+00:00 duration:0.536611
[2024-11-11T11:05:18.947+0000] {logging_mixin.py:190} INFO - Task:<Task(PythonOperator): create_save_df> dag:<DAG: python_op_sample_1> dagrun:<DagRun python_op_sample_1 @ 2024-11-11 11:05:15.719479+00:00: manual__2024-11-11T11:05:15.719479+00:00, state:running, queued_at: 2024-11-11 11:05:15.769661+00:00. externally triggered: True>
[2024-11-11T11:05:18.948+0000] {logging_mixin.py:190} INFO - Failure caused by Cannot save file into a non-existent directory: '/opt/***/__file__'
[2024-11-11T11:05:18.949+0000] {taskinstance.py:1225} INFO - Marking task as UP_FOR_RETRY. dag_id=python_op_sample_1, task_id=create_save_df, run_id=manual__2024-11-11T11:05:15.719479+00:00, execution_date=20241111T110515, start_date=20241111T110518, end_date=20241111T110518
[2024-11-11T11:05:18.985+0000] {taskinstance.py:340} INFO - ::group::Post task execution logs
[2024-11-11T11:05:18.987+0000] {standard_task_runner.py:124} ERROR - Failed to execute job 31 for task create_save_df (Cannot save file into a non-existent directory: '/opt/***/__file__'; 57891)
Traceback (most recent call last):
  File "/home/airflow/.local/lib/python3.12/site-packages/airflow/task/task_runner/standard_task_runner.py", line 117, in _start_by_fork
    ret = args.func(args, dag=self.dag)
          ^^^^^^^^^^^^^^^^^^^^^^^^^^^^^
  File "/home/airflow/.local/lib/python3.12/site-packages/airflow/cli/cli_config.py", line 49, in command
    return func(*args, **kwargs)
           ^^^^^^^^^^^^^^^^^^^^^
  File "/home/airflow/.local/lib/python3.12/site-packages/airflow/utils/cli.py", line 115, in wrapper
    return f(*args, **kwargs)
           ^^^^^^^^^^^^^^^^^^
  File "/home/airflow/.local/lib/python3.12/site-packages/airflow/cli/commands/task_command.py", line 483, in task_run
    task_return_code = _run_task_by_selected_method(args, _dag, ti)
                       ^^^^^^^^^^^^^^^^^^^^^^^^^^^^^^^^^^^^^^^^^^^^
  File "/home/airflow/.local/lib/python3.12/site-packages/airflow/cli/commands/task_command.py", line 256, in _run_task_by_selected_method
    return _run_raw_task(args, ti)
           ^^^^^^^^^^^^^^^^^^^^^^^
  File "/home/airflow/.local/lib/python3.12/site-packages/airflow/cli/commands/task_command.py", line 341, in _run_raw_task
    return ti._run_raw_task(
           ^^^^^^^^^^^^^^^^^
  File "/home/airflow/.local/lib/python3.12/site-packages/airflow/utils/session.py", line 97, in wrapper
    return func(*args, session=session, **kwargs)
           ^^^^^^^^^^^^^^^^^^^^^^^^^^^^^^^^^^^^^^
  File "/home/airflow/.local/lib/python3.12/site-packages/airflow/models/taskinstance.py", line 3004, in _run_raw_task
    return _run_raw_task(
           ^^^^^^^^^^^^^^
  File "/home/airflow/.local/lib/python3.12/site-packages/airflow/models/taskinstance.py", line 273, in _run_raw_task
    TaskInstance._execute_task_with_callbacks(
  File "/home/airflow/.local/lib/python3.12/site-packages/airflow/models/taskinstance.py", line 3158, in _execute_task_with_callbacks
    result = self._execute_task(context, task_orig)
             ^^^^^^^^^^^^^^^^^^^^^^^^^^^^^^^^^^^^^^
  File "/home/airflow/.local/lib/python3.12/site-packages/airflow/models/taskinstance.py", line 3182, in _execute_task
    return _execute_task(self, context, task_orig)
           ^^^^^^^^^^^^^^^^^^^^^^^^^^^^^^^^^^^^^^^
  File "/home/airflow/.local/lib/python3.12/site-packages/airflow/models/taskinstance.py", line 767, in _execute_task
    result = _execute_callable(context=context, **execute_callable_kwargs)
             ^^^^^^^^^^^^^^^^^^^^^^^^^^^^^^^^^^^^^^^^^^^^^^^^^^^^^^^^^^^^^
  File "/home/airflow/.local/lib/python3.12/site-packages/airflow/models/taskinstance.py", line 733, in _execute_callable
    return ExecutionCallableRunner(
           ^^^^^^^^^^^^^^^^^^^^^^^^
  File "/home/airflow/.local/lib/python3.12/site-packages/airflow/utils/operator_helpers.py", line 252, in run
    return self.func(*args, **kwargs)
           ^^^^^^^^^^^^^^^^^^^^^^^^^^
  File "/home/airflow/.local/lib/python3.12/site-packages/airflow/models/baseoperator.py", line 406, in wrapper
    return func(self, *args, **kwargs)
           ^^^^^^^^^^^^^^^^^^^^^^^^^^^
  File "/home/airflow/.local/lib/python3.12/site-packages/airflow/operators/python.py", line 238, in execute
    return_value = self.execute_callable()
                   ^^^^^^^^^^^^^^^^^^^^^^^
  File "/home/airflow/.local/lib/python3.12/site-packages/airflow/operators/python.py", line 256, in execute_callable
    return runner.run(*self.op_args, **self.op_kwargs)
           ^^^^^^^^^^^^^^^^^^^^^^^^^^^^^^^^^^^^^^^^^^^
  File "/home/airflow/.local/lib/python3.12/site-packages/airflow/utils/operator_helpers.py", line 252, in run
    return self.func(*args, **kwargs)
           ^^^^^^^^^^^^^^^^^^^^^^^^^^
  File "/opt/airflow/dags/dag_1_python_op_eg/task1.py", line 11, in create_and_save_df
    data.to_csv(f"{file_path}/py_op_task1.csv", index=False)
  File "/home/airflow/.local/lib/python3.12/site-packages/pandas/core/generic.py", line 3902, in to_csv
    return DataFrameRenderer(formatter).to_csv(
           ^^^^^^^^^^^^^^^^^^^^^^^^^^^^^^^^^^^^
  File "/home/airflow/.local/lib/python3.12/site-packages/pandas/io/formats/format.py", line 1152, in to_csv
    csv_formatter.save()
  File "/home/airflow/.local/lib/python3.12/site-packages/pandas/io/formats/csvs.py", line 247, in save
    with get_handle(
         ^^^^^^^^^^^
  File "/home/airflow/.local/lib/python3.12/site-packages/pandas/io/common.py", line 739, in get_handle
    check_parent_directory(str(handle))
  File "/home/airflow/.local/lib/python3.12/site-packages/pandas/io/common.py", line 604, in check_parent_directory
    raise OSError(rf"Cannot save file into a non-existent directory: '{parent}'")
OSError: Cannot save file into a non-existent directory: '/opt/***/__file__'
[2024-11-11T11:05:19.024+0000] {local_task_job_runner.py:266} INFO - Task exited with return code 1
[2024-11-11T11:05:19.084+0000] {taskinstance.py:3900} INFO - 0 downstream tasks scheduled from follow-on schedule check
[2024-11-11T11:05:19.088+0000] {local_task_job_runner.py:245} INFO - ::endgroup::
