[2024-11-11T12:18:39.966+0000] {local_task_job_runner.py:123} INFO - ::group::Pre task execution logs
[2024-11-11T12:18:39.985+0000] {taskinstance.py:2612} INFO - Dependencies all met for dep_context=non-requeueable deps ti=<TaskInstance: dg-python_operator_dag1.create_df_and_save manual__2024-11-11T12:18:37.739148+00:00 [queued]>
[2024-11-11T12:18:39.996+0000] {taskinstance.py:2612} INFO - Dependencies all met for dep_context=requeueable deps ti=<TaskInstance: dg-python_operator_dag1.create_df_and_save manual__2024-11-11T12:18:37.739148+00:00 [queued]>
[2024-11-11T12:18:39.996+0000] {taskinstance.py:2865} INFO - Starting attempt 1 of 2
[2024-11-11T12:18:40.013+0000] {taskinstance.py:2888} INFO - Executing <Task(PythonOperator): create_df_and_save> on 2024-11-11 12:18:37.739148+00:00
[2024-11-11T12:18:40.023+0000] {warnings.py:112} WARNING - /home/***/.local/lib/python3.12/site-packages/***/task/task_runner/standard_task_runner.py:70: DeprecationWarning: This process (pid=472) is multi-threaded, use of fork() may lead to deadlocks in the child.
  pid = os.fork()

[2024-11-11T12:18:40.026+0000] {standard_task_runner.py:72} INFO - Started process 474 to run task
[2024-11-11T12:18:40.026+0000] {standard_task_runner.py:104} INFO - Running: ['***', 'tasks', 'run', 'dg-python_operator_dag1', 'create_df_and_save', 'manual__2024-11-11T12:18:37.739148+00:00', '--job-id', '49', '--raw', '--subdir', 'DAGS_FOLDER/dg-python_op_dag1.py', '--cfg-path', '/tmp/tmpnvi6fg11']
[2024-11-11T12:18:40.027+0000] {standard_task_runner.py:105} INFO - Job 49: Subtask create_df_and_save
[2024-11-11T12:18:40.086+0000] {task_command.py:467} INFO - Running <TaskInstance: dg-python_operator_dag1.create_df_and_save manual__2024-11-11T12:18:37.739148+00:00 [running]> on host c6d153583c3b
[2024-11-11T12:18:40.214+0000] {taskinstance.py:3131} INFO - Exporting env vars: AIRFLOW_CTX_DAG_OWNER='***' AIRFLOW_CTX_DAG_ID='dg-python_operator_dag1' AIRFLOW_CTX_TASK_ID='create_df_and_save' AIRFLOW_CTX_EXECUTION_DATE='2024-11-11T12:18:37.739148+00:00' AIRFLOW_CTX_TRY_NUMBER='1' AIRFLOW_CTX_DAG_RUN_ID='manual__2024-11-11T12:18:37.739148+00:00'
[2024-11-11T12:18:40.215+0000] {logging_mixin.py:190} INFO - Task instance is in running state
[2024-11-11T12:18:40.215+0000] {logging_mixin.py:190} INFO -  Previous state of the Task instance: queued
[2024-11-11T12:18:40.215+0000] {logging_mixin.py:190} INFO - Current task name:create_df_and_save state:running start_date:2024-11-11 12:18:39.986428+00:00
[2024-11-11T12:18:40.216+0000] {logging_mixin.py:190} INFO - Dag name:dg-python_operator_dag1 and current dag run status:running
[2024-11-11T12:18:40.216+0000] {taskinstance.py:731} INFO - ::endgroup::
[2024-11-11T12:18:40.216+0000] {taskinstance.py:3310} ERROR - Task failed with exception
Traceback (most recent call last):
  File "/home/airflow/.local/lib/python3.12/site-packages/airflow/models/taskinstance.py", line 767, in _execute_task
    result = _execute_callable(context=context, **execute_callable_kwargs)
             ^^^^^^^^^^^^^^^^^^^^^^^^^^^^^^^^^^^^^^^^^^^^^^^^^^^^^^^^^^^^^
  File "/home/airflow/.local/lib/python3.12/site-packages/airflow/models/taskinstance.py", line 733, in _execute_callable
    return ExecutionCallableRunner(
           ^^^^^^^^^^^^^^^^^^^^^^^^
  File "/home/airflow/.local/lib/python3.12/site-packages/airflow/utils/operator_helpers.py", line 252, in run
    return self.func(*args, **kwargs)
           ^^^^^^^^^^^^^^^^^^^^^^^^^^
  File "/home/airflow/.local/lib/python3.12/site-packages/airflow/models/baseoperator.py", line 406, in wrapper
    return func(self, *args, **kwargs)
           ^^^^^^^^^^^^^^^^^^^^^^^^^^^
  File "/home/airflow/.local/lib/python3.12/site-packages/airflow/operators/python.py", line 238, in execute
    return_value = self.execute_callable()
                   ^^^^^^^^^^^^^^^^^^^^^^^
  File "/home/airflow/.local/lib/python3.12/site-packages/airflow/operators/python.py", line 256, in execute_callable
    return runner.run(*self.op_args, **self.op_kwargs)
           ^^^^^^^^^^^^^^^^^^^^^^^^^^^^^^^^^^^^^^^^^^^
  File "/home/airflow/.local/lib/python3.12/site-packages/airflow/utils/operator_helpers.py", line 252, in run
    return self.func(*args, **kwargs)
           ^^^^^^^^^^^^^^^^^^^^^^^^^^
  File "/opt/airflow/dags/py_operator_dag_tasks/task1.py", line 8, in task1
    df = pd.Createdataframe(data)
         ^^^^^^^^^^^^^^^^^^
AttributeError: module 'pandas' has no attribute 'Createdataframe'
[2024-11-11T12:18:40.241+0000] {logging_mixin.py:190} INFO - Task instance in failure state
[2024-11-11T12:18:40.241+0000] {logging_mixin.py:190} INFO - Task start:2024-11-11 12:18:39.986428+00:00 end:2024-11-11 12:18:40.240365+00:00 duration:0.253937
[2024-11-11T12:18:40.242+0000] {logging_mixin.py:190} INFO - Task:<Task(PythonOperator): create_df_and_save> dag:<DAG: dg-python_operator_dag1> dagrun:<DagRun dg-python_operator_dag1 @ 2024-11-11 12:18:37.739148+00:00: manual__2024-11-11T12:18:37.739148+00:00, state:running, queued_at: 2024-11-11 12:18:37.758856+00:00. externally triggered: True>
[2024-11-11T12:18:40.242+0000] {logging_mixin.py:190} INFO - Failure caused by module 'pandas' has no attribute 'Createdataframe'
[2024-11-11T12:18:40.242+0000] {taskinstance.py:1225} INFO - Marking task as UP_FOR_RETRY. dag_id=dg-python_operator_dag1, task_id=create_df_and_save, run_id=manual__2024-11-11T12:18:37.739148+00:00, execution_date=20241111T121837, start_date=20241111T121839, end_date=20241111T121840
[2024-11-11T12:18:40.268+0000] {taskinstance.py:340} INFO - ::group::Post task execution logs
[2024-11-11T12:18:40.269+0000] {standard_task_runner.py:124} ERROR - Failed to execute job 49 for task create_df_and_save (module 'pandas' has no attribute 'Createdataframe'; 474)
Traceback (most recent call last):
  File "/home/airflow/.local/lib/python3.12/site-packages/airflow/task/task_runner/standard_task_runner.py", line 117, in _start_by_fork
    ret = args.func(args, dag=self.dag)
          ^^^^^^^^^^^^^^^^^^^^^^^^^^^^^
  File "/home/airflow/.local/lib/python3.12/site-packages/airflow/cli/cli_config.py", line 49, in command
    return func(*args, **kwargs)
           ^^^^^^^^^^^^^^^^^^^^^
  File "/home/airflow/.local/lib/python3.12/site-packages/airflow/utils/cli.py", line 115, in wrapper
    return f(*args, **kwargs)
           ^^^^^^^^^^^^^^^^^^
  File "/home/airflow/.local/lib/python3.12/site-packages/airflow/cli/commands/task_command.py", line 483, in task_run
    task_return_code = _run_task_by_selected_method(args, _dag, ti)
                       ^^^^^^^^^^^^^^^^^^^^^^^^^^^^^^^^^^^^^^^^^^^^
  File "/home/airflow/.local/lib/python3.12/site-packages/airflow/cli/commands/task_command.py", line 256, in _run_task_by_selected_method
    return _run_raw_task(args, ti)
           ^^^^^^^^^^^^^^^^^^^^^^^
  File "/home/airflow/.local/lib/python3.12/site-packages/airflow/cli/commands/task_command.py", line 341, in _run_raw_task
    return ti._run_raw_task(
           ^^^^^^^^^^^^^^^^^
  File "/home/airflow/.local/lib/python3.12/site-packages/airflow/utils/session.py", line 97, in wrapper
    return func(*args, session=session, **kwargs)
           ^^^^^^^^^^^^^^^^^^^^^^^^^^^^^^^^^^^^^^
  File "/home/airflow/.local/lib/python3.12/site-packages/airflow/models/taskinstance.py", line 3004, in _run_raw_task
    return _run_raw_task(
           ^^^^^^^^^^^^^^
  File "/home/airflow/.local/lib/python3.12/site-packages/airflow/models/taskinstance.py", line 273, in _run_raw_task
    TaskInstance._execute_task_with_callbacks(
  File "/home/airflow/.local/lib/python3.12/site-packages/airflow/models/taskinstance.py", line 3158, in _execute_task_with_callbacks
    result = self._execute_task(context, task_orig)
             ^^^^^^^^^^^^^^^^^^^^^^^^^^^^^^^^^^^^^^
  File "/home/airflow/.local/lib/python3.12/site-packages/airflow/models/taskinstance.py", line 3182, in _execute_task
    return _execute_task(self, context, task_orig)
           ^^^^^^^^^^^^^^^^^^^^^^^^^^^^^^^^^^^^^^^
  File "/home/airflow/.local/lib/python3.12/site-packages/airflow/models/taskinstance.py", line 767, in _execute_task
    result = _execute_callable(context=context, **execute_callable_kwargs)
             ^^^^^^^^^^^^^^^^^^^^^^^^^^^^^^^^^^^^^^^^^^^^^^^^^^^^^^^^^^^^^
  File "/home/airflow/.local/lib/python3.12/site-packages/airflow/models/taskinstance.py", line 733, in _execute_callable
    return ExecutionCallableRunner(
           ^^^^^^^^^^^^^^^^^^^^^^^^
  File "/home/airflow/.local/lib/python3.12/site-packages/airflow/utils/operator_helpers.py", line 252, in run
    return self.func(*args, **kwargs)
           ^^^^^^^^^^^^^^^^^^^^^^^^^^
  File "/home/airflow/.local/lib/python3.12/site-packages/airflow/models/baseoperator.py", line 406, in wrapper
    return func(self, *args, **kwargs)
           ^^^^^^^^^^^^^^^^^^^^^^^^^^^
  File "/home/airflow/.local/lib/python3.12/site-packages/airflow/operators/python.py", line 238, in execute
    return_value = self.execute_callable()
                   ^^^^^^^^^^^^^^^^^^^^^^^
  File "/home/airflow/.local/lib/python3.12/site-packages/airflow/operators/python.py", line 256, in execute_callable
    return runner.run(*self.op_args, **self.op_kwargs)
           ^^^^^^^^^^^^^^^^^^^^^^^^^^^^^^^^^^^^^^^^^^^
  File "/home/airflow/.local/lib/python3.12/site-packages/airflow/utils/operator_helpers.py", line 252, in run
    return self.func(*args, **kwargs)
           ^^^^^^^^^^^^^^^^^^^^^^^^^^
  File "/opt/airflow/dags/py_operator_dag_tasks/task1.py", line 8, in task1
    df = pd.Createdataframe(data)
         ^^^^^^^^^^^^^^^^^^
AttributeError: module 'pandas' has no attribute 'Createdataframe'
[2024-11-11T12:18:40.323+0000] {local_task_job_runner.py:266} INFO - Task exited with return code 1
[2024-11-11T12:18:40.349+0000] {taskinstance.py:3900} INFO - 0 downstream tasks scheduled from follow-on schedule check
[2024-11-11T12:18:40.351+0000] {local_task_job_runner.py:245} INFO - ::endgroup::
